Workbook

Sheet Instrucciones
A1: TRUEQUE IUB · OPERACIÓN DEL EVENTO 30 DE OCTUBRE
A2: Catálogo consolidado de los dos Excel + control de recepción + intercambio 1:1. Los ejemplares NO están disponibles hasta marcarlos PRESENTES y ACEPTADOS.
A4: 1. Antes de abrir | B4: Guarda una copia de este archivo con la fecha del evento. No borres ni sobrescribas los Excel originales.
A5: 2. Recepción del libro | B5: En la hoja Recepcion busca el ID del ejemplar. Marca PRESENTE = SÍ solo si el libro está físicamente en la mesa. Marca ACEPTADO = ACEPTADO o RECHAZADO. Registra estado físico, responsable, hora y observaciones.
A6: 3. Disponibilidad | B6: Un ejemplar solo pasa a DISPONIBLE cuando Recepcion tiene PRESENTE = SÍ y ACEPTADO = ACEPTADO. Si no está presente, queda NO_PRESENTE. Si se rechaza, queda RECHAZADO y se devuelve al participante.
A7: 4. Intercambio 1:1 | B7: En Intercambios registra el ID del libro aportado y el ID del libro entregado. Ambos deben estar DISPONIBLES y ser diferentes. La columna VALIDACION debe decir VÁLIDO. Si dice ERROR, no entregues nada.
A8: 5. Comprobante | B8: Cuando VALIDACION sea VÁLIDO, el número de operación aparece en COMPROBANTE. Imprime o anota ese número. El catálogo mostrará ambos ejemplares como INTERCAMBIADO.
A9: 6. Anulación / recuperación | B9: Si hubo un error, cambia ESTADO de la operación a ANULADO. No borres la fila. Los ejemplares vuelven a quedar disponibles y la operación conserva el historial.
A10: 7. Duplicados | B10: La hoja Duplicados marca libros repetidos dentro del mismo Excel o entre los dos Excel. No los elimines automáticamente. Verifica físicamente si son ejemplares distintos. Si es el mismo libro, recibe y marca solo uno.
A11: 8. Respaldo | B11: Guarda el archivo después de cada operación. Al cierre, exporta una copia y entrégala al responsable. No subas este archivo a la web pública ni compartas datos de participantes.
A13: Regla de oro: si no está verificado físicamente, no está disponible. Si VALIDACION no dice VÁLIDO, no se entrega.

Sheet Catalogo
A1: ID_EJEMPLAR | B1: ID_BIBLIOGRAFICO | C1: TITULO | D1: AUTOR | E1: EDITORIAL | F1: ISBN | G1: CODIGO_EJEMPLAR | H1: CODIGO_FUENTE | I1: PROCEDENCIA | J1: FILA_ORIGEN | K1: NO_ORIGEN | L1: EJEMPLAR_ORIGEN | M1: OBSERVACIONES | N1: DUPLICADO | O1: ESTADO_RECEPCION | P1: DISPONIBLE_RECEPCION | Q1: ESTADO_EVENTO | R1: RESPONSABLE_RECEPCION | S1: HORA_RECEPCION | T1: OBS_RECEPCION
A2: CH-003 | B2: BIB-001 | C2: Acompañada, pero a solas con la vida | D2: Johana Brewne Kelly | E2: San Barbara | F2: 9789585810358 | G2: CH-003 | H2: ITEM 3 | I2: Libros para el Trueque Literario CH.xlsx | J2: 4 | K2: 3 | M2: Posible duplicado de: INV-063 (INVENTARIO) | N2: POSIBLE_DUPLICADO_ENTRE_FUENTES | O2: =IFERROR(IF(VLOOKUP($A2,Recepcion!$A$2:$I$85,4,FALSE)="SÍ",IF(VLOOKUP($A2,Recepcion!$A$2:$I$85,5,FALSE)="ACEPTADO","DISPONIBLE",IF(VLOOKUP($A2,Recepcion!$A$2:$I$85,5,FALSE)="RECHAZADO","RECHAZADO","PENDIENTE_VERIFICACION")),IF(VLOOKUP($A2,Recepcion!$A$2:$I$85,4,FALSE)="NO","NO_PRESENTE","PENDIENTE_VERIFICACION")),"PENDIENTE_VERIFICACION") | P2: =IF(O2="DISPONIBLE","SÍ","NO") | Q2: =IF(COUNTIFS(Intercambios!$D$4:$D$103,A2,Intercambios!$G$4:$G$103,"REGISTRADO",Intercambios!$J$4:$J$103,"VÁLIDO")+COUNTIFS(Intercambios!$E$4:$E$103,A2,Intercambios!$G$4:$G$103,"REGISTRADO",Intercambios!$J$4:$J$103,"VÁLIDO")>0,"INTERCAMBIADO",O2) | R2: =IFERROR(VLOOKUP($A2,Recepcion!$A$2:$I$85,7,FALSE),"") | S2: =IFERROR(VLOOKUP($A2,Recepcion!$A$2:$I$85,8,FALSE),"") | T2: =IFERROR(VLOOKUP($A2,Recepcion!$A$2:$I$85,9,FALSE),"")
A3: INV-063 | B3: BIB-001 | C3: Acompañada, pero a solas con la vida | D3: Kelly Johana Brewne | E3: San Barbara | G3: INV-063 | H3: EJEMPLAR 1 | I3: INVENTARIO TRUEQUE.xlsx | J3: 65 | K3: 63 | L3: 1 | M3: Posible duplicado de: CH-003 (CH) | N3: POSIBLE_DUPLICADO_ENTRE_FUENTES | O3: =IFERROR(IF(VLOOKUP($A3,Recepcion!$A$2:$I$85,4,FALSE)="SÍ",IF(VLOOKUP($A3,Recepcion!$A$2:$I$85,5,FALSE)="ACEPTADO","DISPONIBLE",IF(VLOOKUP($A3,Recepcion!$A$2:$I$85,5,FALSE)="RECHAZADO","RECHAZADO","PENDIENTE_VERIFICACION")),IF(VLOOKUP($A3,Recepcion!$A$2:$I$85,4,FALSE)="NO","NO_PRESENTE","PENDIENTE_VERIFICACION")),"PENDIENTE_VERIFICACION") | P3: =IF(O3="DISPONIBLE","SÍ","NO") | Q3: =IF(COUNTIFS(Intercambios!$D$4:$D$103,A3,Intercambios!$G$4:$G$103,"REGISTRADO",Intercambios!$J$4:$J$103,"VÁLIDO")+COUNTIFS(Intercambios!$E$4:$E$103,A3,Intercambios!$G$4:$G$103,"REGISTRADO",Intercambios!$J$4:$J$103,"VÁLIDO")>0,"INTERCAMBIADO",O3) | R3: =IFERROR(VLOOKUP($A3,Recepcion!$A$2:$I$85,7,FALSE),"") | S3: =IFERROR(VLOOKUP($A3,Recepcion!$A$2:$I$85,8,FALSE),"") | T3: =IFERROR(VLOOKUP($A3,Recepcion!$A$2:$I$85,9,FALSE),"")
A4: INV-053 | B4: BIB-002 | C4: Bailando con Lobos | D4: Michael Blake | E4: RBA | G4: INV-053 | H4: EJEMPLAR 1 | I4: INVENTARIO TRUEQUE.xlsx | J4: 55 | K4: 53 | L4: 1 | O4: =IFERROR(IF(VLOOKUP($A4,Recepcion!$A$2:$I$85,4,FALSE)="SÍ",IF(VLOOKUP($A4,Recepcion!$A$2:$I$85,5,FALSE)="ACEPTADO","DISPONIBLE",IF(VLOOKUP($A4,Recepcion!$A$2:$I$85,5,FALSE)="RECHAZADO","RECHAZADO","PENDIENTE_VERIFICACION")),IF(VLOOKUP($A4,Recepcion!$A$2:$I$85,4,FALSE)="NO","NO_PRESENTE","PENDIENTE_VERIFICACION")),"PENDIENTE_VERIFICACION") | P4: =IF(O4="DISPONIBLE","SÍ","NO") | Q4: =IF(COUNTIFS(Intercambios!$D$4:$D$103,A4,Intercambios!$G$4:$G$103,"REGISTRADO",Intercambios!$J$4:$J$103,"VÁLIDO")+COUNTIFS(Intercambios!$E$4:$E$103,A4,Intercambios!$G$4:$G$103,"REGISTRADO",Intercambios!$J$4:$J$103,"VÁLIDO")>0,"INTERCAMBIADO",O4) | R4: =IFERROR(VLOOKUP($A4,Recepcion!$A$2:$I$85,7,FALSE),"") | S4: =IFERROR(VLOOKUP($A4,Recepcion!$A$2:$I$85,8,FALSE),"") | T4: =IFERROR(VLOOKUP($A4,Recepcion!$A$2:$I$85,9,FALSE),"")
A5: INV-009 | B5: BIB-003 | C5: Bajo la Luna de Mayo | D5: Gerardo Meneses | E5: Norma | G5: INV-009 | H5: EJEMPLAR 1 | I5: INVENTARIO TRUEQUE.xlsx | J5: 11 | K5: 9 | L5: 1 | O5: =IFERROR(IF(VLOOKUP($A5,Recepcion!$A$2:$I$85,4,FALSE)="SÍ",IF(VLOOKUP($A5,Recepcion!$A$2:$I$85,5,FALSE)="ACEPTADO","DISPONIBLE",IF(VLOOKUP($A5,Recepcion!$A$2:$I$85,5,FALSE)="RECHAZADO","RECHAZADO","PENDIENTE_VERIFICACION")),IF(VLOOKUP($A5,Recepcion!$A$2:$I$85,4,FALSE)="NO","NO_PRESENTE","PENDIENTE_VERIFICACION")),"PENDIENTE_VERIFICACION") | P5: =IF(O5="DISPONIBLE","SÍ","NO") | Q5: =IF(COUNTIFS(Intercambios!$D$4:$D$103,A5,Intercambios!$G$4:$G$103,"REGISTRADO",Intercambios!$J$4:$J$103,"VÁLIDO")+COUNTIFS(Intercambios!$E$4:$E$103,A5,Intercambios!$G$4:$G$103,"REGISTRADO",Intercambios!$J$4:$J$103,"VÁLIDO")>0,"INTERCAMBIADO",O5) | R5: =IFERROR(VLOOKUP($A5,Recepcion!$A$2:$I$85,7,FALSE),"") | S5: =IFERROR(VLOOKUP($A5,Recepcion!$A$2:$I$85,8,FALSE),"") | T5: =IFERROR(VLOOKUP($A5,Recepcion!$A$2:$I$85,9,FALSE),"")
A6: INV-049 | B6: BIB-004 | C6: Bajo la Misma Estrella | D6: John Green | E6: N/E | G6: INV-049 | H6: EJEMPLAR 1 | I6: INVENTARIO TRUEQUE.xlsx | J6: 51 | K6: 49 | L6: 1 | O6: =IFERROR(IF(VLOOKUP($A6,Recepcion!$A$2:$I$85,4,FALSE)="SÍ",IF(VLOOKUP($A6,Recepcion!$A$2:$I$85,5,FALSE)="ACEPTADO","DISPONIBLE",IF(VLOOKUP($A6,Recepcion!$A$2:$I$85,5,FALSE)="RECHAZADO","RECHAZADO","PENDIENTE_VERIFICACION")),IF(VLOOKUP($A6,Recepcion!$A$2:$I$85,4,FALSE)="NO","NO_PRESENTE","PENDIENTE_VERIFICACION")),"PENDIENTE_VERIFICACION") | P6: =IF(O6="DISPONIBLE","SÍ","NO") | Q6: =IF(COUNTIFS(Intercambios!$D$4:$D$103,A6,Intercambios!$G$4:$G$103,"REGISTRADO",Intercambios!$J$4:$J$103,"VÁLIDO")+COUNTIFS(Intercambios!$E$4:$E$103,A6,Intercambios!$G$4:$G$103,"REGISTRADO",Intercambios!$J$4:$J$103,"VÁLIDO")>0,"INTERCAMBIADO",O6) | R6: =IFERROR(VLOOKUP($A6,Recepcion!$A$2:$I$85,7,FALSE),"") | S6: =IFERROR(VLOOKUP($A6,Recepcion!$A$2:$I$85,8,FALSE),"") | T6: =IFERROR(VLOOKUP($A6,Recepcion!$A$2:$I$85,9,FALSE),"")
A7: INV-027 | B7: BIB-005 | C7: Boulevard | D7: Flor Salvador | E7: Naranja | G7: INV-027 | H7: EJEMPLAR 1 | I7: INVENTARIO TRUEQUE.xlsx | J7: 29 | K7: 27 | L7: 1 | O7: =IFERROR(IF(VLOOKUP($A7,Recepcion!$A$2:$I$85,4,FALSE)="SÍ",IF(VLOOKUP($A7,Recepcion!$A$2:$I$85,5,FALSE)="ACEPTADO","DISPONIBLE",IF(VLOOKUP($A7,Recepcion!$A$2:$I$85,5,FALSE)="RECHAZADO","RECHAZADO","PENDIENTE_VERIFICACION")),IF(VLOOKUP($A7,Recepcion!$A$2:$I$85,4,FALSE)="NO","NO_PRESENTE","PENDIENTE_VERIFICACION")),"PENDIENTE_VERIFICACION") | P7: =IF(O7="DISPONIBLE","SÍ","NO") | Q7: =IF(COUNTIFS(Intercambios!$D$4:$D$103,A7,Intercambios!$G$4:$G$103,"REGISTRADO",Intercambios!$J$4:$J$103,"VÁLIDO")+COUNTIFS(Intercambios!$E$4:$E$103,A7,Intercambios!$G$4:$G$103,"REGISTRADO",Intercambios!$J$4:$J$103,"VÁLIDO")>0,"INTERCAMBIADO",O7) | R7: =IFERROR(VLOOKUP($A7,Recepcion!$A$2:$I$85,7,FALSE),"") | S7: =IFERROR(VLOOKUP($A7,Recepcion!$A$2:$I$85,8,FALSE),"") | T7: =IFERROR(VLOOKUP($A7,Recepcion!$A$2:$I$85,9,FALSE),"")
A8: INV-044 | B8: BIB-006 | C8: Chat Natacha Chat | D8: Luis Maria Pescetti | E8: Alfaguara Juvenil | G8: INV-044 | H8: EJEMPLAR 1 | I8: INVENTARIO TRUEQUE.xlsx | J8: 46 | K8: 44 | L8: 1 | O8: =IFERROR(IF(VLOOKUP($A8,Recepcion!$A$2:$I$85,4,FALSE)="SÍ",IF(VLOOKUP($A8,Recepcion!$A$2:$I$85,5,FALSE)="ACEPTADO","DISPONIBLE",IF(VLOOKUP($A8,Recepcion!$A$2:$I$85,5,FALSE)="RECHAZADO","RECHAZADO","PENDIENTE_VERIFICACION")),IF(VLOOKUP($A8,Recepcion!$A$2:$I$85,4,FALSE)="NO","NO_PRESENTE","PENDIENTE_VERIFICACION")),"PENDIENTE_VERIFICACION") | P8: =IF(O8="DISPONIBLE","SÍ","NO") | Q8: =IF(COUNTIFS(Intercambios!$D$4:$D$103,A8,Intercambios!$G$4:$G$103,"REGISTRADO",Intercambios!$J$4:$J$103,"VÁLIDO")+COUNTIFS(Intercambios!$E$4:$E$103,A8,Intercambios!$G$4:$G$103,"REGISTRADO",Intercambios!$J$4:$J$103,"VÁLIDO")>0,"INTERCAMBIADO",O8) | R8: =IFERROR(VLOOKUP($A8,Recepcion!$A$2:$I$85,7,FALSE),"") | S8: =IFERROR(VLOOKUP($A8,Recepcion!$A$2:$I$85,8,FALSE),"") | T8: =IFERROR(VLOOKUP($A8,Recepcion!$A$2:$I$85,9,FALSE),"")
A9: INV-056 | B9: BIB-007 | C9: ¿Chicos de la Calle o Trabajo Chico? | D9: Jose Manuel Grima, Alicia le Fur | E9: Lumen Hymanitas | G9: INV-056 | H9: EJEMPLAR 1 | I9: INVENTARIO TRUEQUE.xlsx | J9: 58 | K9: 56 | L9: 1 | O9: =IFERROR(IF(VLOOKUP($A9,Recepcion!$A$2:$I$85,4,FALSE)="SÍ",IF(VLOOKUP($A9,Recepcion!$A$2:$I$85,5,FALSE)="ACEPTADO","DISPONIBLE",IF(VLOOKUP($A9,Recepcion!$A$2:$I$85,5,FALSE)="RECHAZADO","RECHAZADO","PENDIENTE_VERIFICACION")),IF(VLOOKUP($A9,Recepcion!$A$2:$I$85,4,FALSE)="NO","NO_PRESENTE","PENDIENTE_VERIFICACION")),"PENDIENTE_VERIFICACION") | P9: =IF(O9="DISPONIBLE","SÍ","NO") | Q9: =IF(COUNTIFS(Intercambios!$D$4:$D$103,A9,Intercambios!$G$4:$G$103,"REGISTRADO",Intercambios!$J$4:$J$103,"VÁLIDO")+COUNTIFS(Intercambios!$E$4:$E$103,A9,Intercambios!$G$4:$G$103,"REGISTRADO",Intercambios!$J$4:$J$103,"VÁLIDO")>0,"INTERCAMBIADO",O9) | R9: =IFERROR(VLOOKUP($A9,Recepcion!$A$2:$I$85,7,FALSE),"") | S9: =IFERROR(VLOOKUP($A9,Recepcion!$A$2:$I$85,8,FALSE),"") | T9: =IFERROR(VLOOKUP($A9,Recepcion!$A$2:$I$85,9,FALSE),"")
A10: INV-029 | B10: BIB-008 | C10: Cien Años de Soledad | D10: Gabriel Garcia Marquez | E10: Norma | G10: INV-029 | H10: EJEMPLAR 1 | I10: INVENTARIO TRUEQUE.xlsx | J10: 31 | K10: 29 | L10: 1 | O10: =IFERROR(IF(VLOOKUP($A10,Recepcion!$A$2:$I$85,4,FALSE)="SÍ",IF(VLOOKUP($A10,Recepcion!$A$2:$I$85,5,FALSE)="ACEPTADO","DISPONIBLE",IF(VLOOKUP($A10,Recepcion!$A$2:$I$85,5,FALSE)="RECHAZADO","RECHAZADO","PENDIENTE_VERIFICACION")),IF(VLOOKUP($A10,Recepcion!$A$2:$I$85,4,FALSE)="NO","NO_PRESENTE","PENDIENTE_VERIFICACION")),"PENDIENTE_VERIFICACION") | P10: =IF(O10="DISPONIBLE","SÍ","NO") | Q10: =IF(COUNTIFS(Intercambios!$D$4:$D$103,A10,Intercambios!$G$4:$G$103,"REGISTRADO",Intercambios!$J$4:$J$103,"VÁLIDO")+COUNTIFS(Intercambios!$E$4:$E$103,A10,Intercambios!$G$4:$G$103,"REGISTRADO",Intercambios!$J$4:$J$103,"VÁLIDO")>0,"INTERCAMBIADO",O10) | R10: =IFERROR(VLOOKUP($A10,Recepcion!$A$2:$I$85,7,FALSE),"") | S10: =IFERROR(VLOOKUP($A10,Recepcion!$A$2:$I$85,8,FALSE),"") | T10: =IFERROR(VLOOKUP($A10,Recepcion!$A$2:$I$85,9,FALSE),"")
A11: CH-002 | B11: BIB-009 | C11: Con el alma en la mano | D11: Perret Gentil Beatriz | E11: San Barbara | F11: 9789585837515 | G11: CH-002 | H11: ITEM 2 | I11: Libros para el Trueque Literario CH.xlsx | J11: 3 | K11: 2 | M11: Posible duplicado de: INV-062 (INVENTARIO) | N11: POSIBLE_DUPLICADO_ENTRE_FUENTES | O11: =IFERROR(IF(VLOOKUP($A11,Recepcion!$A$2:$I$85,4,FALSE)="SÍ",IF(VLOOKUP($A11,Recepcion!$A$2:$I$85,5,FALSE)="ACEPTADO","DISPONIBLE",IF(VLOOKUP($A11,Recepcion!$A$2:$I$85,5,FALSE)="RECHAZADO","RECHAZADO","PENDIENTE_VERIFICACION")),IF(VLOOKUP($A11,Recepcion!$A$2:$I$85,4,FALSE)="NO","NO_PRESENTE","PENDIENTE_VERIFICACION")),"PENDIENTE_VERIFICACION") | P11: =IF(O11="DISPONIBLE","SÍ","NO") | Q11: =IF(COUNTIFS(Intercambios!$D$4:$D$103,A11,Intercambios!$G$4:$G$103,"REGISTRADO",Intercambios!$J$4:$J$103,"VÁLIDO")+COUNTIFS(Intercambios!$E$4:$E$103,A11,Intercambios!$G$4:$G$103,"REGISTRADO",Intercambios!$J$4:$J$103,"VÁLIDO")>0,"INTERCAMBIADO",O11) | R11: =IFERROR(VLOOKUP($A11,Recepcion!$A$2:$I$85,7,FALSE),"") | S11: =IFERROR(VLOOKUP($A11,Recepcion!$A$2:$I$85,8,FALSE),"") | T11: =IFERROR(VLOOKUP($A11,Recepcion!$A$2:$I$85,9,FALSE),"")
A12: INV-062 | B12: BIB-009 | C12: Con el alma en la mano | D12: Beatriz Perret Gentil | E12: San Barbara | G12: INV-062 | H12: EJEMPLAR 1 | I12: INVENTARIO TRUEQUE.xlsx | J12: 64 | K12: 62 | L12: 1 | M12: Posible duplicado de: CH-002 (CH) | N12: POSIBLE_DUPLICADO_ENTRE_FUENTES | O12: =IFERROR(IF(VLOOKUP($A12,Recepcion!$A$2:$I$85,4,FALSE)="SÍ",IF(VLOOKUP($A12,Recepcion!$A$2:$I$85,5,FALSE)="ACEPTADO","DISPONIBLE",IF(VLOOKUP($A12,Recepcion!$A$2:$I$85,5,FALSE)="RECHAZADO","RECHAZADO","PENDIENTE_VERIFICACION")),IF(VLOOKUP($A12,Recepcion!$A$2:$I$85,4,FALSE)="NO","NO_PRESENTE","PENDIENTE_VERIFICACION")),"PENDIENTE_VERIFICACION") | P12: =IF(O12="DISPONIBLE","SÍ","NO") | Q12: =IF(COUNTIFS(Intercambios!$D$4:$D$103,A12,Intercambios!$G$4:$G$103,"REGISTRADO",Intercambios!$J$4:$J$103,"VÁLIDO")+COUNTIFS(Intercambios!$E$4:$E$103,A12,Intercambios!$G$4:$G$103,"REGISTRADO",Intercambios!$J$4:$J$103,"VÁLIDO")>0,"INTERCAMBIADO",O12) | R12: =IFERROR(VLOOKUP($A12,Recepcion!$A$2:$I$85,7,FALSE),"") | S12: =IFERROR(VLOOKUP($A12,Recepcion!$A$2:$I$85,8,FALSE),"") | T12: =IFERROR(VLOOKUP($A12,Recepcion!$A$2:$I$85,9,FALSE),"")
A13: INV-007 | B13: BIB-010 | C13: Conversaciones con Dios | D13: Neale Donald | E13: Debolsillo | G13: INV-007 | H13: EJEMPLAR 1 | I13: INVENTARIO TRUEQUE.xlsx | J13: 9 | K13: 7 | L13: 1 | O13: =IFERROR(IF(VLOOKUP($A13,Recepcion!$A$2:$I$85,4,FALSE)="SÍ",IF(VLOOKUP($A13,Recepcion!$A$2:$I$85,5,FALSE)="ACEPTADO","DISPONIBLE",IF(VLOOKUP($A13,Recepcion!$A$2:$I$85,5,FALSE)="RECHAZADO","RECHAZADO","PENDIENTE_VERIFICACION")),IF(VLOOKUP($A13,Recepcion!$A$2:$I$85,4,FALSE)="NO","NO_PRESENTE","PENDIENTE_VERIFICACION")),"PENDIENTE_VERIFICACION") | P13: =IF(O13="DISPONIBLE","SÍ","NO") | Q13: =IF(COUNTIFS(Intercambios!$D$4:$D$103,A13,Intercambios!$G$4:$G$103,"REGISTRADO",Intercambios!$J$4:$J$103,"VÁLIDO")+COUNTIFS(Intercambios!$E$4:$E$103,A13,Intercambios!$G$4:$G$103,"REGISTRADO",Intercambios!$J$4:$J$103,"VÁLIDO")>0,"INTERCAMBIADO",O13) | R13: =IFERROR(VLOOKUP($A13,Recepcion!$A$2:$I$85,7,FALSE),"") | S13: =IFERROR(VLOOKUP($A13,Recepcion!$A$2:$I$85,8,FALSE),"") | T13: =IFERROR(VLOOKUP($A13,Recepcion!$A$2:$I$85,9,FALSE),"")
A14: INV-050 | B14: BIB-011 | C14: Cronicas de una Muerte Anunciada | D14: Gabriel Garcia Marquez | E14: N/E | G14: INV-050 | H14: EJEMPLAR 1 | I14: INVENTARIO TRUEQUE.xlsx | J14: 52 | K14: 50 | L14: 1 | O14: =IFERROR(IF(VLOOKUP($A14,Recepcion!$A$2:$I$85,4,FALSE)="SÍ",IF(VLOOKUP($A14,Recepcion!$A$2:$I$85,5,FALSE)="ACEPTADO","DISPONIBLE",IF(VLOOKUP($A14,Recepcion!$A$2:$I$85,5,FALSE)="RECHAZADO","RECHAZADO","PENDIENTE_VERIFICACION")),IF(VLOOKUP($A14,Recepcion!$A$2:$I$85,4,FALSE)="NO","NO_PRESENTE","PENDIENTE_VERIFICACION")),"PENDIENTE_VERIFICACION") | P14: =IF(O14="DISPONIBLE","SÍ","NO") | Q14: =IF(COUNTIFS(Intercambios!$D$4:$D$103,A14,Intercambios!$G$4:$G$103,"REGISTRADO",Intercambios!$J$4:$J$103,"VÁLIDO")+COUNTIFS(Intercambios!$E$4:$E$103,A14,Intercambios!$G$4:$G$103,"REGISTRADO",Intercambios!$J$4:$J$103,"VÁLIDO")>0,"INTERCAMBIADO",O14) | R14: =IFERROR(VLOOKUP($A14,Recepcion!$A$2:$I$85,7,FALSE),"") | S14: =IFERROR(VLOOKUP($A14,Recepcion!$A$2:$I$85,8,FALSE),"") | T14: =IFERROR(VLOOKUP($A14,Recepcion!$A$2:$I$85,9,FALSE),"")
A15: CH-008 | B15: BIB-012 | C15: Cuando despierte el viento | D15: Heredia Maria F. | E15: Norma | F15: 9789580009658 | G15: CH-008 | H15: ITEM 8 | I15: Libros para el Trueque Literario CH.xlsx | J15: 9 | K15: 8 | O15: =IFERROR(IF(VLOOKUP($A15,Recepcion!$A$2:$I$85,4,FALSE)="SÍ",IF(VLOOKUP($A15,Recepcion!$A$2:$I$85,5,FALSE)="ACEPTADO","DISPONIBLE",IF(VLOOKUP($A15,Recepcion!$A$2:$I$85,5,FALSE)="RECHAZADO","RECHAZADO","PENDIENTE_VERIFICACION")),IF(VLOOKUP($A15,Recepcion!$A$2:$I$85,4,FALSE)="NO","NO_PRESENTE","PENDIENTE_VERIFICACION")),"PENDIENTE_VERIFICACION") | P15: =IF(O15="DISPONIBLE","SÍ","NO") | Q15: =IF(COUNTIFS(Intercambios!$D$4:$D$103,A15,Intercambios!$G$4:$G$103,"REGISTRADO",Intercambios!$J$4:$J$103,"VÁLIDO")+COUNTIFS(Intercambios!$E$4:$E$103,A15,Intercambios!$G$4:$G$103,"REGISTRADO",Intercambios!$J$4:$J$103,"VÁLIDO")>0,"INTERCAMBIADO",O15) | R15: =IFERROR(VLOOKUP($A15,Recepcion!$A$2:$I$85,7,FALSE),"") | S15: =IFERROR(VLOOKUP($A15,Recepcion!$A$2:$I$85,8,FALSE),"") | T15: =IFERROR(VLOOKUP($A15,Recepcion!$A$2:$I$85,9,FALSE),"")
A16: CH-007 | B16: BIB-013 | C16: Cumbia Soul | D16: Maria T. Balogh | E16: Cool Way Press | F16: 9780990972914 | G16: CH-007 | H16: ITEM 7 | I16: Libros para el Trueque Literario CH.xlsx | J16: 8 | K16: 7 | M16: Posible duplicado de: INV-067 (INVENTARIO) | N16: POSIBLE_DUPLICADO_ENTRE_FUENTES | O16: =IFERROR(IF(VLOOKUP($A16,Recepcion!$A$2:$I$85,4,FALSE)="SÍ",IF(VLOOKUP($A16,Recepcion!$A$2:$I$85,5,FALSE)="ACEPTADO","DISPONIBLE",IF(VLOOKUP($A16,Recepcion!$A$2:$I$85,5,FALSE)="RECHAZADO","RECHAZADO","PENDIENTE_VERIFICACION")),IF(VLOOKUP($A16,Recepcion!$A$2:$I$85,4,FALSE)="NO","NO_PRESENTE","PENDIENTE_VERIFICACION")),"PENDIENTE_VERIFICACION") | P16: =IF(O16="DISPONIBLE","SÍ","NO") | Q16: =IF(COUNTIFS(Intercambios!$D$4:$D$103,A16,Intercambios!$G$4:$G$103,"REGISTRADO",Intercambios!$J$4:$J$103,"VÁLIDO")+COUNTIFS(Intercambios!$E$4:$E$103,A16,Intercambios!$G$4:$G$103,"REGISTRADO",Intercambios!$J$4:$J$103,"VÁLIDO")>0,"INTERCAMBIADO",O16) | R16: =IFERROR(VLOOKUP($A16,Recepcion!$A$2:$I$85,7,FALSE),"") | S16: =IFERROR(VLOOKUP($A16,Recepcion!$A$2:$I$85,8,FALSE),"") | T16: =IFERROR(VLOOKUP($A16,Recepcion!$A$2:$I$85,9,FALSE),"")
A17: INV-067 | B17: BIB-013 | C17: Cumbia Soul | D17: Maria T. Balogh | E17: Cool Way Press | G17: INV-067 | H17: EJEMPLAR 1 | I17: INVENTARIO TRUEQUE.xlsx | J17: 69 | K17: 67 | L17: 1 | M17: Posible duplicado de: CH-007 (CH) | N17: POSIBLE_DUPLICADO_ENTRE_FUENTES | O17: =IFERROR(IF(VLOOKUP($A17,Recepcion!$A$2:$I$85,4,FALSE)="SÍ",IF(VLOOKUP($A17,Recepcion!$A$2:$I$85,5,FALSE)="ACEPTADO","DISPONIBLE",IF(VLOOKUP($A17,Recepcion!$A$2:$I$85,5,FALSE)="RECHAZADO","RECHAZADO","PENDIENTE_VERIFICACION")),IF(VLOOKUP($A17,Recepcion!$A$2:$I$85,4,FALSE)="NO","NO_PRESENTE","PENDIENTE_VERIFICACION")),"PENDIENTE_VERIFICACION") | P17: =IF(O17="DISPONIBLE","SÍ","NO") | Q17: =IF(COUNTIFS(Intercambios!$D$4:$D$103,A17,Intercambios!$G$4:$G$103,"REGISTRADO",Intercambios!$J$4:$J$103,"VÁLIDO")+COUNTIFS(Intercambios!$E$4:$E$103,A17,Intercambios!$G$4:$G$103,"REGISTRADO",Intercambios!$J$4:$J$103,"VÁLIDO")>0,"INTERCAMBIADO",O17) | R17: =IFERROR(VLOOKUP($A17,Recepcion!$A$2:$I$85,7,FALSE),"") | S17: =IFERROR(VLOOKUP($A17,Recepcion!$A$2:$I$85,8,FALSE),"") | T17: =IFERROR(VLOOKUP($A17,Recepcion!$A$2:$I$85,9,FALSE),"")
A18: CH-005 | B18: BIB-014 | C18: De Rejas y Amor | D18: Barreira Maria Arturo | E18: San Barbara | F18: 9789585837591 | G18: CH-005 | H18: ITEM 5 | I18: Libros para el Trueque Literario CH.xlsx | J18: 6 | K18: 5 | M18: Posible duplicado de: INV-065 (INVENTARIO) | N18: POSIBLE_DUPLICADO_ENTRE_FUENTES | O18: =IFERROR(IF(VLOOKUP($A18,Recepcion!$A$2:$I$85,4,FALSE)="SÍ",IF(VLOOKUP($A18,Recepcion!$A$2:$I$85,5,FALSE)="ACEPTADO","DISPONIBLE",IF(VLOOKUP($A18,Recepcion!$A$2:$I$85,5,FALSE)="RECHAZADO","RECHAZADO","PENDIENTE_VERIFICACION")),IF(VLOOKUP($A18,Recepcion!$A$2:$I$85,4,FALSE)="NO","NO_PRESENTE","PENDIENTE_VERIFICACION")),"PENDIENTE_VERIFICACION") | P18: =IF(O18="DISPONIBLE","SÍ","NO") | Q18: =IF(COUNTIFS(Intercambios!$D$4:$D$103,A18,Intercambios!$G$4:$G$103,"REGISTRADO",Intercambios!$J$4:$J$103,"VÁLIDO")+COUNTIFS(Intercambios!$E$4:$E$103,A18,Intercambios!$G$4:$G$103,"REGISTRADO",Intercambios!$J$4:$J$103,"VÁLIDO")>0,"INTERCAMBIADO",O18) | R18: =IFERROR(VLOOKUP($A18,Recepcion!$A$2:$I$85,7,FALSE),"") | S18: =IFERROR(VLOOKUP($A18,Recepcion!$A$2:$I$85,8,FALSE),"") | T18: =IFERROR(VLOOKUP($A18,Recepcion!$A$2:$I$85,9,FALSE),"")
A19: INV-065 | B19: BIB-014 | C19: De Rejas y Amor | D19: Arturo Barreira Maria | E19: San Barbara | G19: INV-065 | H19: EJEMPLAR 1 | I19: INVENTARIO TRUEQUE.xlsx | J19: 67 | K19: 65 | L19: 1 | M19: Posible duplicado de: CH-005 (CH) | N19: POSIBLE_DUPLICADO_ENTRE_FUENTES | O19: =IFERROR(IF(VLOOKUP($A19,Recepcion!$A$2:$I$85,4,FALSE)="SÍ",IF(VLOOKUP($A19,Recepcion!$A$2:$I$85,5,FALSE)="ACEPTADO","DISPONIBLE",IF(VLOOKUP($A19,Recepcion!$A$2:$I$85,5,FALSE)="RECHAZADO","RECHAZADO","PENDIENTE_VERIFICACION")),IF(VLOOKUP($A19,Recepcion!$A$2:$I$85,4,FALSE)="NO","NO_PRESENTE","PENDIENTE_VERIFICACION")),"PENDIENTE_VERIFICACION") | P19: =IF(O19="DISPONIBLE","SÍ","NO") | Q19: =IF(COUNTIFS(Intercambios!$D$4:$D$103,A19,Intercambios!$G$4:$G$103,"REGISTRADO",Intercambios!$J$4:$J$103,"VÁLIDO")+COUNTIFS(Intercambios!$E$4:$E$103,A19,Intercambios!$G$4:$G$103,"REGISTRADO",Intercambios!$J$4:$J$103,"VÁLIDO")>0,"INTERCAMBIADO",O19) | R19: =IFERROR(VLOOKUP($A19,Recepcion!$A$2:$I$85,7,FALSE),"") | S19: =IFERROR(VLOOKUP($A19,Recepcion!$A$2:$I$85,8,FALSE),"") | T19: =IFERROR(VLOOKUP($A19,Recepcion!$A$2:$I$85,9,FALSE),"")
A20: INV-023 | B20: BIB-015 | C20: Del Secuestro y Otras Muertes | D20: Camilo Romero | E20: Intermedio | G20: INV-023 | H20: EJEMPLAR 1 | I20: INVENTARIO TRUEQUE.xlsx | J20: 25 | K20: 23 | L20: 1 | O20: =IFERROR(IF(VLOOKUP($A20,Recepcion!$A$2:$I$85,4,FALSE)="SÍ",IF(VLOOKUP($A20,Recepcion!$A$2:$I$85,5,FALSE)="ACEPTADO","DISPONIBLE",IF(VLOOKUP($A20,Recepcion!$A$2:$I$85,5,FALSE)="RECHAZADO","RECHAZADO","PENDIENTE_VERIFICACION")),IF(VLOOKUP($A20,Recepcion!$A$2:$I$85,4,FALSE)="NO","NO_PRESENTE","PENDIENTE_VERIFICACION")),"PENDIENTE_VERIFICACION") | P20: =IF(O20="DISPONIBLE","SÍ","NO") | Q20: =IF(COUNTIFS(Intercambios!$D$4:$D$103,A20,Intercambios!$G$4:$G$103,"REGISTRADO",Intercambios!$J$4:$J$103,"VÁLIDO")+COUNTIFS(Intercambios!$E$4:$E$103,A20,Intercambios!$G$4:$G$103,"REGISTRADO",Intercambios!$J$4:$J$103,"VÁLIDO")>0,"INTERCAMBIADO",O20) | R20: =IFERROR(VLOOKUP($A20,Recepcion!$A$2:$I$85,7,FALSE),"") | S20: =IFERROR(VLOOKUP($A20,Recepcion!$A$2:$I$85,8,FALSE),"") | T20: =IFERROR(VLOOKUP($A20,Recepcion!$A$2:$I$85,9,FALSE),"")
A21: INV-004 | B21: BIB-016 | C21: Despues de el. Secuela | D21: Flor Salvador | E21: N/E | G21: INV-004 | H21: EJEMPLAR 1 | I21: INVENTARIO TRUEQUE.xlsx | J21: 6 | K21: 4 | L21: 1 | O21: =IFERROR(IF(VLOOKUP($A21,Recepcion!$A$2:$I$85,4,FALSE)="SÍ",IF(VLOOKUP($A21,Recepcion!$A$2:$I$85,5,FALSE)="ACEPTADO","DISPONIBLE",IF(VLOOKUP($A21,Recepcion!$A$2:$I$85,5,FALSE)="RECHAZADO","RECHAZADO","PENDIENTE_VERIFICACION")),IF(VLOOKUP($A21,Recepcion!$A$2:$I$85,4,FALSE)="NO","NO_PRESENTE","PENDIENTE_VERIFICACION")),"PENDIENTE_VERIFICACION") | P21: =IF(O21="DISPONIBLE","SÍ","NO") | Q21: =IF(COUNTIFS(Intercambios!$D$4:$D$103,A21,Intercambios!$G$4:$G$103,"REGISTRADO",Intercambios!$J$4:$J$103,"VÁLIDO")+COUNTIFS(Intercambios!$E$4:$E$103,A21,Intercambios!$G$4:$G$103,"REGISTRADO",Intercambios!$J$4:$J$103,"VÁLIDO")>0,"INTERCAMBIADO",O21) | R21: =IFERROR(VLOOKUP($A21,Recepcion!$A$2:$I$85,7,FALSE),"") | S21: =IFERROR(VLOOKUP($A21,Recepcion!$A$2:$I$85,8,FALSE),"") | T21: =IFERROR(VLOOKUP($A21,Recepcion!$A$2:$I$85,9,FALSE),"")
A22: INV-054 | B22: BIB-017 | C22: Duespues del Funeral | D22: Agatha Christie | E22: Circulo de Lectores | G22: INV-054 | H22: EJEMPLAR 1 | I22: INVENTARIO TRUEQUE.xlsx | J22: 56 | K22: 54 | L22: 1 | O22: =IFERROR(IF(VLOOKUP($A22,Recepcion!$A$2:$I$85,4,FALSE)="SÍ",IF(VLOOKUP($A22,Recepcion!$A$2:$I$85,5,FALSE)="ACEPTADO","DISPONIBLE",IF(VLOOKUP($A22,Recepcion!$A$2:$I$85,5,FALSE)="RECHAZADO","RECHAZADO","PENDIENTE_VERIFICACION")),IF(VLOOKUP($A22,Recepcion!$A$2:$I$85,4,FALSE)="NO","NO_PRESENTE","PENDIENTE_VERIFICACION")),"PENDIENTE_VERIFICACION") | P22: =IF(O22="DISPONIBLE","SÍ","NO") | Q22: =IF(COUNTIFS(Intercambios!$D$4:$D$103,A22,Intercambios!$G$4:$G$103,"REGISTRADO",Intercambios!$J$4:$J$103,"VÁLIDO")+COUNTIFS(Intercambios!$E$4:$E$103,A22,Intercambios!$G$4:$G$103,"REGISTRADO",Intercambios!$J$4:$J$103,"VÁLIDO")>0,"INTERCAMBIADO",O22) | R22: =IFERROR(VLOOKUP($A22,Recepcion!$A$2:$I$85,7,FALSE),"") | S22: =IFERROR(VLOOKUP($A22,Recepcion!$A$2:$I$85,8,FALSE),"") | T22: =IFERROR(VLOOKUP($A22,Recepcion!$A$2:$I$85,9,FALSE),"")
A23: CH-011 | B23: BIB-018 | C23: El Abrazo | D23: Bojunga Lygia | E23: Norma | F23: 9789580471578 | G23: CH-011 | H23: ITEM 11 | I23: Libros para el Trueque Literario CH.xlsx | J23: 12 | K23: 11 | O23: =IFERROR(IF(VLOOKUP($A23,Recepcion!$A$2:$I$85,4,FALSE)="SÍ",IF(VLOOKUP($A23,Recepcion!$A$2:$I$85,5,FALSE)="ACEPTADO","DISPONIBLE",IF(VLOOKUP($A23,Recepcion!$A$2:$I$85,5,FALSE)="RECHAZADO","RECHAZADO","PENDIENTE_VERIFICACION")),IF(VLOOKUP($A23,Recepcion!$A$2:$I$85,4,FALSE)="NO","NO_PRESENTE","PENDIENTE_VERIFICACION")),"PENDIENTE_VERIFICACION") | P23: =IF(O23="DISPONIBLE","SÍ","NO") | Q23: =IF(COUNTIFS(Intercambios!$D$4:$D$103,A23,Intercambios!$G$4:$G$103,"REGISTRADO",Intercambios!$J$4:$J$103,"VÁLIDO")+COUNTIFS(Intercambios!$E$4:$E$103,A23,Intercambios!$G$4:$G$103,"REGISTRADO",Intercambios!$J$4:$J$103,"VÁLIDO")>0,"INTERCAMBIADO",O23) | R23: =IFERROR(VLOOKUP($A23,Recepcion!$A$2:$I$85,7,FALSE),"") | S23: =IFERROR(VLOOKUP($A23,Recepcion!$A$2:$I$85,8,FALSE),"") | T23: =IFERROR(VLOOKUP($A23,Recepcion!$A$2:$I$85,9,FALSE),"")
A24: INV-013 | B24: BIB-019 | C24: El Alquimista | D24: Paulo Coelho | E24: N/E | G24: INV-013 | H24: EJEMPLAR 1 | I24: INVENTARIO TRUEQUE.xlsx | J24: 15 | K24: 13 | L24: 1 | O24: =IFERROR(IF(VLOOKUP($A24,Recepcion!$A$2:$I$85,4,FALSE)="SÍ",IF(VLOOKUP($A24,Recepcion!$A$2:$I$85,5,FALSE)="ACEPTADO","DISPONIBLE",IF(VLOOKUP($A24,Recepcion!$A$2:$I$85,5,FALSE)="RECHAZADO","RECHAZADO","PENDIENTE_VERIFICACION")),IF(VLOOKUP($A24,Recepcion!$A$2:$I$85,4,FALSE)="NO","NO_PRESENTE","PENDIENTE_VERIFICACION")),"PENDIENTE_VERIFICACION") | P24: =IF(O24="DISPONIBLE","SÍ","NO") | Q24: =IF(COUNTIFS(Intercambios!$D$4:$D$103,A24,Intercambios!$G$4:$G$103,"REGISTRADO",Intercambios!$J$4:$J$103,"VÁLIDO")+COUNTIFS(Intercambios!$E$4:$E$103,A24,Intercambios!$G$4:$G$103,"REGISTRADO",Intercambios!$J$4:$J$103,"VÁLIDO")>0,"INTERCAMBIADO",O24) | R24: =IFERROR(VLOOKUP($A24,Recepcion!$A$2:$I$85,7,FALSE),"") | S24: =IFERROR(VLOOKUP($A24,Recepcion!$A$2:$I$85,8,FALSE),"") | T24: =IFERROR(VLOOKUP($A24,Recepcion!$A$2:$I$85,9,FALSE),"")
A25: INV-005 | B25: BIB-020 | C25: El Camino de la Felicidad | D25: Jorge Bucay | E25: Debolsillo | G25: INV-005 | H25: EJEMPLAR 1 | I25: INVENTARIO TRUEQUE.xlsx | J25: 7 | K25: 5 | L25: 1 | O25: =IFERROR(IF(VLOOKUP($A25,Recepcion!$A$2:$I$85,4,FALSE)="SÍ",IF(VLOOKUP($A25,Recepcion!$A$2:$I$85,5,FALSE)="ACEPTADO","DISPONIBLE",IF(VLOOKUP($A25,Recepcion!$A$2:$I$85,5,FALSE)="RECHAZADO","RECHAZADO","PENDIENTE_VERIFICACION")),IF(VLOOKUP($A25,Recepcion!$A$2:$I$85,4,FALSE)="NO","NO_PRESENTE","PENDIENTE_VERIFICACION")),"PENDIENTE_VERIFICACION") | P25: =IF(O25="DISPONIBLE","SÍ","NO") | Q25: =IF(COUNTIFS(Intercambios!$D$4:$D$103,A25,Intercambios!$G$4:$G$103,"REGISTRADO",Intercambios!$J$4:$J$103,"VÁLIDO")+COUNTIFS(Intercambios!$E$4:$E$103,A25,Intercambios!$G$4:$G$103,"REGISTRADO",Intercambios!$J$4:$J$103,"VÁLIDO")>0,"INTERCAMBIADO",O25) | R25: =IFERROR(VLOOKUP($A25,Recepcion!$A$2:$I$85,7,FALSE),"") | S25: =IFERROR(VLOOKUP($A25,Recepcion!$A$2:$I$85,8,FALSE),"") | T25: =IFERROR(VLOOKUP($A25,Recepcion!$A$2:$I$85,9,FALSE),"")
A26: INV-021 | B26: BIB-021 | C26: El Cuaderno de Notas de Miguel | D26: Pedro Conrado Cudriz | E26: Sibila | G26: INV-021 | H26: EJEMPLAR 1 | I26: INVENTARIO TRUEQUE.xlsx | J26: 23 | K26: 21 | L26: 1 | O26: =IFERROR(IF(VLOOKUP($A26,Recepcion!$A$2:$I$85,4,FALSE)="SÍ",IF(VLOOKUP($A26,Recepcion!$A$2:$I$85,5,FALSE)="ACEPTADO","DISPONIBLE",IF(VLOOKUP($A26,Recepcion!$A$2:$I$85,5,FALSE)="RECHAZADO","RECHAZADO","PENDIENTE_VERIFICACION")),IF(VLOOKUP($A26,Recepcion!$A$2:$I$85,4,FALSE)="NO","NO_PRESENTE","PENDIENTE_VERIFICACION")),"PENDIENTE_VERIFICACION") | P26: =IF(O26="DISPONIBLE","SÍ","NO") | Q26: =IF(COUNTIFS(Intercambios!$D$4:$D$103,A26,Intercambios!$G$4:$G$103,"REGISTRADO",Intercambios!$J$4:$J$103,"VÁLIDO")+COUNTIFS(Intercambios!$E$4:$E$103,A26,Intercambios!$G$4:$G$103,"REGISTRADO",Intercambios!$J$4:$J$103,"VÁLIDO")>0,"INTERCAMBIADO",O26) | R26: =IFERROR(VLOOKUP($A26,Recepcion!$A$2:$I$85,7,FALSE),"") | S26: =IFERROR(VLOOKUP($A26,Recepcion!$A$2:$I$85,8,FALSE),"") | T26: =IFERROR(VLOOKUP($A26,Recepcion!$A$2:$I$85,9,FALSE),"")
A27: INV-045 | B27: BIB-022 | C27: El Dia del Odio | D27: Osorio Lizarazo | E27: N/E | G27: INV-045 | H27: EJEMPLAR 1 | I27: INVENTARIO TRUEQUE.xlsx | J27: 47 | K27: 45 | L27: 1 | O27: =IFERROR(IF(VLOOKUP($A27,Recepcion!$A$2:$I$85,4,FALSE)="SÍ",IF(VLOOKUP($A27,Recepcion!$A$2:$I$85,5,FALSE)="ACEPTADO","DISPONIBLE",IF(VLOOKUP($A27,Recepcion!$A$2:$I$85,5,FALSE)="RECHAZADO","RECHAZADO","PENDIENTE_VERIFICACION")),IF(VLOOKUP($A27,Recepcion!$A$2:$I$85,4,FALSE)="NO","NO_PRESENTE","PENDIENTE_VERIFICACION")),"PENDIENTE_VERIFICACION") | P27: =IF(O27="DISPONIBLE","SÍ","NO") | Q27: =IF(COUNTIFS(Intercambios!$D$4:$D$103,A27,Intercambios!$G$4:$G$103,"REGISTRADO",Intercambios!$J$4:$J$103,"VÁLIDO")+COUNTIFS(Intercambios!$E$4:$E$103,A27,Intercambios!$G$4:$G$103,"REGISTRADO",Intercambios!$J$4:$J$103,"VÁLIDO")>0,"INTERCAMBIADO",O27) | R27: =IFERROR(VLOOKUP($A27,Recepcion!$A$2:$I$85,7,FALSE),"") | S27: =IFERROR(VLOOKUP($A27,Recepcion!$A$2:$I$85,8,FALSE),"") | T27: =IFERROR(VLOOKUP($A27,Recepcion!$A$2:$I$85,9,FALSE),"")
A28: INV-057 | B28: BIB-023 | C28: El Diablo de la Botella | D28: Robert Louis Stevenson | E28: Norma | G28: INV-057 | H28: EJEMPLAR 1 | I28: INVENTARIO TRUEQUE.xlsx | J28: 59 | K28: 57 | L28: 1 | O28: =IFERROR(IF(VLOOKUP($A28,Recepcion!$A$2:$I$85,4,FALSE)="SÍ",IF(VLOOKUP($A28,Recepcion!$A$2:$I$85,5,FALSE)="ACEPTADO","DISPONIBLE",IF(VLOOKUP($A28,Recepcion!$A$2:$I$85,5,FALSE)="RECHAZADO","RECHAZADO","PENDIENTE_VERIFICACION")),IF(VLOOKUP($A28,Recepcion!$A$2:$I$85,4,FALSE)="NO","NO_PRESENTE","PENDIENTE_VERIFICACION")),"PENDIENTE_VERIFICACION") | P28: =IF(O28="DISPONIBLE","SÍ","NO") | Q28: =IF(COUNTIFS(Intercambios!$D$4:$D$103,A28,Intercambios!$G$4:$G$103,"REGISTRADO",Intercambios!$J$4:$J$103,"VÁLIDO")+COUNTIFS(Intercambios!$E$4:$E$103,A28,Intercambios!$G$4:$G$103,"REGISTRADO",Intercambios!$J$4:$J$103,"VÁLIDO")>0,"INTERCAMBIADO",O28) | R28: =IFERROR(VLOOKUP($A28,Recepcion!$A$2:$I$85,7,FALSE),"") | S28: =IFERROR(VLOOKUP($A28,Recepcion!$A$2:$I$85,8,FALSE),"") | T28: =IFERROR(VLOOKUP($A28,Recepcion!$A$2:$I$85,9,FALSE),"")
A29: INV-035 | B29: BIB-024 | C29: El Extraño Caso del DR. Jekylly MR. Hyde | D29: Stevenson | E29: Norma | G29: INV-035 | H29: EJEMPLAR 1 | I29: INVENTARIO TRUEQUE.xlsx | J29: 37 | K29: 35 | L29: 1 | O29: =IFERROR(IF(VLOOKUP($A29,Recepcion!$A$2:$I$85,4,FALSE)="SÍ",IF(VLOOKUP($A29,Recepcion!$A$2:$I$85,5,FALSE)="ACEPTADO","DISPONIBLE",IF(VLOOKUP($A29,Recepcion!$A$2:$I$85,5,FALSE)="RECHAZADO","RECHAZADO","PENDIENTE_VERIFICACION")),IF(VLOOKUP($A29,Recepcion!$A$2:$I$85,4,FALSE)="NO","NO_PRESENTE","PENDIENTE_VERIFICACION")),"PENDIENTE_VERIFICACION") | P29: =IF(O29="DISPONIBLE","SÍ","NO") | Q29: =IF(COUNTIFS(Intercambios!$D$4:$D$103,A29,Intercambios!$G$4:$G$103,"REGISTRADO",Intercambios!$J$4:$J$103,"VÁLIDO")+COUNTIFS(Intercambios!$E$4:$E$103,A29,Intercambios!$G$4:$G$103,"REGISTRADO",Intercambios!$J$4:$J$103,"VÁLIDO")>0,"INTERCAMBIADO",O29) | R29: =IFERROR(VLOOKUP($A29,Recepcion!$A$2:$I$85,7,FALSE),"") | S29: =IFERROR(VLOOKUP($A29,Recepcion!$A$2:$I$85,8,FALSE),"") | T29: =IFERROR(VLOOKUP($A29,Recepcion!$A$2:$I$85,9,FALSE),"")
A30: INV-026 | B30: BIB-025 | C30: El Higado de Prometeo | D30: Jorge Bustos | E30: Nobel | G30: INV-026 | H30: EJEMPLAR 1 | I30: INVENTARIO TRUEQUE.xlsx | J30: 28 | K30: 26 | L30: 1 | O30: =IFERROR(IF(VLOOKUP($A30,Recepcion!$A$2:$I$85,4,FALSE)="SÍ",IF(VLOOKUP($A30,Recepcion!$A$2:$I$85,5,FALSE)="ACEPTADO","DISPONIBLE",IF(VLOOKUP($A30,Recepcion!$A$2:$I$85,5,FALSE)="RECHAZADO","RECHAZADO","PENDIENTE_VERIFICACION")),IF(VLOOKUP($A30,Recepcion!$A$2:$I$85,4,FALSE)="NO","NO_PRESENTE","PENDIENTE_VERIFICACION")),"PENDIENTE_VERIFICACION") | P30: =IF(O30="DISPONIBLE","SÍ","NO") | Q30: =IF(COUNTIFS(Intercambios!$D$4:$D$103,A30,Intercambios!$G$4:$G$103,"REGISTRADO",Intercambios!$J$4:$J$103,"VÁLIDO")+COUNTIFS(Intercambios!$E$4:$E$103,A30,Intercambios!$G$4:$G$103,"REGISTRADO",Intercambios!$J$4:$J$103,"VÁLIDO")>0,"INTERCAMBIADO",O30) | R30: =IFERROR(VLOOKUP($A30,Recepcion!$A$2:$I$85,7,FALSE),"") | S30: =IFERROR(VLOOKUP($A30,Recepcion!$A$2:$I$85,8,FALSE),"") | T30: =IFERROR(VLOOKUP($A30,Recepcion!$A$2:$I$85,9,FALSE),"")
A31: CH-016 | B31: BIB-026 | C31: El joven Moriarty y la planta carnivora | D31: Rhei Sofía | E31: Norma | F31: 9789587768114 | G31: CH-016 | H31: ITEM 16 | I31: Libros para el Trueque Literario CH.xlsx | J31: 17 | K31: 16 | O31: =IFERROR(IF(VLOOKUP($A31,Recepcion!$A$2:$I$85,4,FALSE)="SÍ",IF(VLOOKUP($A31,Recepcion!$A$2:$I$85,5,FALSE)="ACEPTADO","DISPONIBLE",IF(VLOOKUP($A31,Recepcion!$A$2:$I$85,5,FALSE)="RECHAZADO","RECHAZADO","PENDIENTE_VERIFICACION")),IF(VLOOKUP($A31,Recepcion!$A$2:$I$85,4,FALSE)="NO","NO_PRESENTE","PENDIENTE_VERIFICACION")),"PENDIENTE_VERIFICACION") | P31: =IF(O31="DISPONIBLE","SÍ","NO") | Q31: =IF(COUNTIFS(Intercambios!$D$4:$D$103,A31,Intercambios!$G$4:$G$103,"REGISTRADO",Intercambios!$J$4:$J$103,"VÁLIDO")+COUNTIFS(Intercambios!$E$4:$E$103,A31,Intercambios!$G$4:$G$103,"REGISTRADO",Intercambios!$J$4:$J$103,"VÁLIDO")>0,"INTERCAMBIADO",O31) | R31: =IFERROR(VLOOKUP($A31,Recepcion!$A$2:$I$85,7,FALSE),"") | S31: =IFERROR(VLOOKUP($A31,Recepcion!$A$2:$I$85,8,FALSE),"") | T31: =IFERROR(VLOOKUP($A31,Recepcion!$A$2:$I$85,9,FALSE),"")
A32: INV-033 | B32: BIB-027 | C32: El Llano en Llamas | D32: Juan Rulfo | E32: N/E | G32: INV-033 | H32: EJEMPLAR 1 | I32: INVENTARIO TRUEQUE.xlsx | J32: 35 | K32: 33 | L32: 1 | O32: =IFERROR(IF(VLOOKUP($A32,Recepcion!$A$2:$I$85,4,FALSE)="SÍ",IF(VLOOKUP($A32,Recepcion!$A$2:$I$85,5,FALSE)="ACEPTADO","DISPONIBLE",IF(VLOOKUP($A32,Recepcion!$A$2:$I$85,5,FALSE)="RECHAZADO","RECHAZADO","PENDIENTE_VERIFICACION")),IF(VLOOKUP($A32,Recepcion!$A$2:$I$85,4,FALSE)="NO","NO_PRESENTE","PENDIENTE_VERIFICACION")),"PENDIENTE_VERIFICACION") | P32: =IF(O32="DISPONIBLE","SÍ","NO") | Q32: =IF(COUNTIFS(Intercambios!$D$4:$D$103,A32,Intercambios!$G$4:$G$103,"REGISTRADO",Intercambios!$J$4:$J$103,"VÁLIDO")+COUNTIFS(Intercambios!$E$4:$E$103,A32,Intercambios!$G$4:$G$103,"REGISTRADO",Intercambios!$J$4:$J$103,"VÁLIDO")>0,"INTERCAMBIADO",O32) | R32: =IFERROR(VLOOKUP($A32,Recepcion!$A$2:$I$85,7,FALSE),"") | S32: =IFERROR(VLOOKUP($A32,Recepcion!$A$2:$I$85,8,FALSE),"") | T32: =IFERROR(VLOOKUP($A32,Recepcion!$A$2:$I$85,9,FALSE),"")
A33: INV-019 | B33: BIB-028 | C33: El Lobo y los Siete Cabritos | D33: Christine NÖstlinger | E33: Norma | G33: INV-019 | H33: EJEMPLAR 1 | I33: INVENTARIO TRUEQUE.xlsx | J33: 21 | K33: 19 | L33: 1 | O33: =IFERROR(IF(VLOOKUP($A33,Recepcion!$A$2:$I$85,4,FALSE)="SÍ",IF(VLOOKUP($A33,Recepcion!$A$2:$I$85,5,FALSE)="ACEPTADO","DISPONIBLE",IF(VLOOKUP($A33,Recepcion!$A$2:$I$85,5,FALSE)="RECHAZADO","RECHAZADO","PENDIENTE_VERIFICACION")),IF(VLOOKUP($A33,Recepcion!$A$2:$I$85,4,FALSE)="NO","NO_PRESENTE","PENDIENTE_VERIFICACION")),"PENDIENTE_VERIFICACION") | P33: =IF(O33="DISPONIBLE","SÍ","NO") | Q33: =IF(COUNTIFS(Intercambios!$D$4:$D$103,A33,Intercambios!$G$4:$G$103,"REGISTRADO",Intercambios!$J$4:$J$103,"VÁLIDO")+COUNTIFS(Intercambios!$E$4:$E$103,A33,Intercambios!$G$4:$G$103,"REGISTRADO",Intercambios!$J$4:$J$103,"VÁLIDO")>0,"INTERCAMBIADO",O33) | R33: =IFERROR(VLOOKUP($A33,Recepcion!$A$2:$I$85,7,FALSE),"") | S33: =IFERROR(VLOOKUP($A33,Recepcion!$A$2:$I$85,8,FALSE),"") | T33: =IFERROR(VLOOKUP($A33,Recepcion!$A$2:$I$85,9,FALSE),"")
A34: INV-025 | B34: BIB-029 | C34: El Manuscrito Encontrado en Accra | D34: Paulo Coelho | E34: Grijalbo | G34: INV-025 | H34: EJEMPLAR 1 | I34: INVENTARIO TRUEQUE.xlsx | J34: 27 | K34: 25 | L34: 1 | O34: =IFERROR(IF(VLOOKUP($A34,Recepcion!$A$2:$I$85,4,FALSE)="SÍ",IF(VLOOKUP($A34,Recepcion!$A$2:$I$85,5,FALSE)="ACEPTADO","DISPONIBLE",IF(VLOOKUP($A34,Recepcion!$A$2:$I$85,5,FALSE)="RECHAZADO","RECHAZADO","PENDIENTE_VERIFICACION")),IF(VLOOKUP($A34,Recepcion!$A$2:$I$85,4,FALSE)="NO","NO_PRESENTE","PENDIENTE_VERIFICACION")),"PENDIENTE_VERIFICACION") | P34: =IF(O34="DISPONIBLE","SÍ","NO") | Q34: =IF(COUNTIFS(Intercambios!$D$4:$D$103,A34,Intercambios!$G$4:$G$103,"REGISTRADO",Intercambios!$J$4:$J$103,"VÁLIDO")+COUNTIFS(Intercambios!$E$4:$E$103,A34,Intercambios!$G$4:$G$103,"REGISTRADO",Intercambios!$J$4:$J$103,"VÁLIDO")>0,"INTERCAMBIADO",O34) | R34: =IFERROR(VLOOKUP($A34,Recepcion!$A$2:$I$85,7,FALSE),"") | S34: =IFERROR(VLOOKUP($A34,Recepcion!$A$2:$I$85,8,FALSE),"") | T34: =IFERROR(VLOOKUP($A34,Recepcion!$A$2:$I$85,9,FALSE),"")
A35: INV-011 | B35: BIB-030 | C35: El Mejor Poema del Mundo 2026 | D35: Celia Corral Cañas | E35: Ediciones Noel | G35: INV-011 | H35: EJEMPLAR 1 | I35: INVENTARIO TRUEQUE.xlsx | J35: 13 | K35: 11 | L35: 1 | O35: =IFERROR(IF(VLOOKUP($A35,Recepcion!$A$2:$I$85,4,FALSE)="SÍ",IF(VLOOKUP($A35,Recepcion!$A$2:$I$85,5,FALSE)="ACEPTADO","DISPONIBLE",IF(VLOOKUP($A35,Recepcion!$A$2:$I$85,5,FALSE)="RECHAZADO","RECHAZADO","PENDIENTE_VERIFICACION")),IF(VLOOKUP($A35,Recepcion!$A$2:$I$85,4,FALSE)="NO","NO_PRESENTE","PENDIENTE_VERIFICACION")),"PENDIENTE_VERIFICACION") | P35: =IF(O35="DISPONIBLE","SÍ","NO") | Q35: =IF(COUNTIFS(Intercambios!$D$4:$D$103,A35,Intercambios!$G$4:$G$103,"REGISTRADO",Intercambios!$J$4:$J$103,"VÁLIDO")+COUNTIFS(Intercambios!$E$4:$E$103,A35,Intercambios!$G$4:$G$103,"REGISTRADO",Intercambios!$J$4:$J$103,"VÁLIDO")>0,"INTERCAMBIADO",O35) | R35: =IFERROR(VLOOKUP($A35,Recepcion!$A$2:$I$85,7,FALSE),"") | S35: =IFERROR(VLOOKUP($A35,Recepcion!$A$2:$I$85,8,FALSE),"") | T35: =IFERROR(VLOOKUP($A35,Recepcion!$A$2:$I$85,9,FALSE),"")
A36: INV-024 | B36: BIB-031 | C36: El Paisaje de una Amistad | D36: Angel Esteban, Stephanie Panichelli | E36: Espasa e Hoy | G36: INV-024 | H36: EJEMPLAR 1 | I36: INVENTARIO TRUEQUE.xlsx | J36: 26 | K36: 24 | L36: 1 | O36: =IFERROR(IF(VLOOKUP($A36,Recepcion!$A$2:$I$85,4,FALSE)="SÍ",IF(VLOOKUP($A36,Recepcion!$A$2:$I$85,5,FALSE)="ACEPTADO","DISPONIBLE",IF(VLOOKUP($A36,Recepcion!$A$2:$I$85,5,FALSE)="RECHAZADO","RECHAZADO","PENDIENTE_VERIFICACION")),IF(VLOOKUP($A36,Recepcion!$A$2:$I$85,4,FALSE)="NO","NO_PRESENTE","PENDIENTE_VERIFICACION")),"PENDIENTE_VERIFICACION") | P36: =IF(O36="DISPONIBLE","SÍ","NO") | Q36: =IF(COUNTIFS(Intercambios!$D$4:$D$103,A36,Intercambios!$G$4:$G$103,"REGISTRADO",Intercambios!$J$4:$J$103,"VÁLIDO")+COUNTIFS(Intercambios!$E$4:$E$103,A36,Intercambios!$G$4:$G$103,"REGISTRADO",Intercambios!$J$4:$J$103,"VÁLIDO")>0,"INTERCAMBIADO",O36) | R36: =IFERROR(VLOOKUP($A36,Recepcion!$A$2:$I$85,7,FALSE),"") | S36: =IFERROR(VLOOKUP($A36,Recepcion!$A$2:$I$85,8,FALSE),"") | T36: =IFERROR(VLOOKUP($A36,Recepcion!$A$2:$I$85,9,FALSE),"")
A37: INV-010 | B37: BIB-032 | C37: El Quinto Dragon | D37: Paulina Aguilar Gutierrez | E37: Norma | G37: INV-010 | H37: EJEMPLAR 1 | I37: INVENTARIO TRUEQUE.xlsx | J37: 12 | K37: 10 | L37: 1 | O37: =IFERROR(IF(VLOOKUP($A37,Recepcion!$A$2:$I$85,4,FALSE)="SÍ",IF(VLOOKUP($A37,Recepcion!$A$2:$I$85,5,FALSE)="ACEPTADO","DISPONIBLE",IF(VLOOKUP($A37,Recepcion!$A$2:$I$85,5,FALSE)="RECHAZADO","RECHAZADO","PENDIENTE_VERIFICACION")),IF(VLOOKUP($A37,Recepcion!$A$2:$I$85,4,FALSE)="NO","NO_PRESENTE","PENDIENTE_VERIFICACION")),"PENDIENTE_VERIFICACION") | P37: =IF(O37="DISPONIBLE","SÍ","NO") | Q37: =IF(COUNTIFS(Intercambios!$D$4:$D$103,A37,Intercambios!$G$4:$G$103,"REGISTRADO",Intercambios!$J$4:$J$103,"VÁLIDO")+COUNTIFS(Intercambios!$E$4:$E$103,A37,Intercambios!$G$4:$G$103,"REGISTRADO",Intercambios!$J$4:$J$103,"VÁLIDO")>0,"INTERCAMBIADO",O37) | R37: =IFERROR(VLOOKUP($A37,Recepcion!$A$2:$I$85,7,FALSE),"") | S37: =IFERROR(VLOOKUP($A37,Recepcion!$A$2:$I$85,8,FALSE),"") | T37: =IFERROR(VLOOKUP($A37,Recepcion!$A$2:$I$85,9,FALSE),"")
A38: INV-020 | B38: BIB-033 | C38: El Refugio de Poder Olvidar | D38: Maria Cristina Ocampo de Manzano | E38: N/E | G38: INV-020 | H38: EJEMPLAR 1 | I38: INVENTARIO TRUEQUE.xlsx | J38: 22 | K38: 20 | L38: 1 | O38: =IFERROR(IF(VLOOKUP($A38,Recepcion!$A$2:$I$85,4,FALSE)="SÍ",IF(VLOOKUP($A38,Recepcion!$A$2:$I$85,5,FALSE)="ACEPTADO","DISPONIBLE",IF(VLOOKUP($A38,Recepcion!$A$2:$I$85,5,FALSE)="RECHAZADO","RECHAZADO","PENDIENTE_VERIFICACION")),IF(VLOOKUP($A38,Recepcion!$A$2:$I$85,4,FALSE)="NO","NO_PRESENTE","PENDIENTE_VERIFICACION")),"PENDIENTE_VERIFICACION") | P38: =IF(O38="DISPONIBLE","SÍ","NO") | Q38: =IF(COUNTIFS(Intercambios!$D$4:$D$103,A38,Intercambios!$G$4:$G$103,"REGISTRADO",Intercambios!$J$4:$J$103,"VÁLIDO")+COUNTIFS(Intercambios!$E$4:$E$103,A38,Intercambios!$G$4:$G$103,"REGISTRADO",Intercambios!$J$4:$J$103,"VÁLIDO")>0,"INTERCAMBIADO",O38) | R38: =IFERROR(VLOOKUP($A38,Recepcion!$A$2:$I$85,7,FALSE),"") | S38: =IFERROR(VLOOKUP($A38,Recepcion!$A$2:$I$85,8,FALSE),"") | T38: =IFERROR(VLOOKUP($A38,Recepcion!$A$2:$I$85,9,FALSE),"")
A39: INV-043 | B39: BIB-034 | C39: El Tunel | D39: Ernesto Sabato | E39: N/E | G39: INV-043 | H39: EJEMPLAR 1 | I39: INVENTARIO TRUEQUE.xlsx | J39: 45 | K39: 43 | L39: 1 | O39: =IFERROR(IF(VLOOKUP($A39,Recepcion!$A$2:$I$85,4,FALSE)="SÍ",IF(VLOOKUP($A39,Recepcion!$A$2:$I$85,5,FALSE)="ACEPTADO","DISPONIBLE",IF(VLOOKUP($A39,Recepcion!$A$2:$I$85,5,FALSE)="RECHAZADO","RECHAZADO","PENDIENTE_VERIFICACION")),IF(VLOOKUP($A39,Recepcion!$A$2:$I$85,4,FALSE)="NO","NO_PRESENTE","PENDIENTE_VERIFICACION")),"PENDIENTE_VERIFICACION") | P39: =IF(O39="DISPONIBLE","SÍ","NO") | Q39: =IF(COUNTIFS(Intercambios!$D$4:$D$103,A39,Intercambios!$G$4:$G$103,"REGISTRADO",Intercambios!$J$4:$J$103,"VÁLIDO")+COUNTIFS(Intercambios!$E$4:$E$103,A39,Intercambios!$G$4:$G$103,"REGISTRADO",Intercambios!$J$4:$J$103,"VÁLIDO")>0,"INTERCAMBIADO",O39) | R39: =IFERROR(VLOOKUP($A39,Recepcion!$A$2:$I$85,7,FALSE),"") | S39: =IFERROR(VLOOKUP($A39,Recepcion!$A$2:$I$85,8,FALSE),"") | T39: =IFERROR(VLOOKUP($A39,Recepcion!$A$2:$I$85,9,FALSE),"")
A40: INV-039 | B40: BIB-035 | C40: El Viejo y El Mar | D40: Ernest Hemingway | E40: Atenea | G40: INV-039 | H40: EJEMPLAR 1 | I40: INVENTARIO TRUEQUE.xlsx | J40: 41 | K40: 39 | L40: 1 | O40: =IFERROR(IF(VLOOKUP($A40,Recepcion!$A$2:$I$85,4,FALSE)="SÍ",IF(VLOOKUP($A40,Recepcion!$A$2:$I$85,5,FALSE)="ACEPTADO","DISPONIBLE",IF(VLOOKUP($A40,Recepcion!$A$2:$I$85,5,FALSE)="RECHAZADO","RECHAZADO","PENDIENTE_VERIFICACION")),IF(VLOOKUP($A40,Recepcion!$A$2:$I$85,4,FALSE)="NO","NO_PRESENTE","PENDIENTE_VERIFICACION")),"PENDIENTE_VERIFICACION") | P40: =IF(O40="DISPONIBLE","SÍ","NO") | Q40: =IF(COUNTIFS(Intercambios!$D$4:$D$103,A40,Intercambios!$G$4:$G$103,"REGISTRADO",Intercambios!$J$4:$J$103,"VÁLIDO")+COUNTIFS(Intercambios!$E$4:$E$103,A40,Intercambios!$G$4:$G$103,"REGISTRADO",Intercambios!$J$4:$J$103,"VÁLIDO")>0,"INTERCAMBIADO",O40) | R40: =IFERROR(VLOOKUP($A40,Recepcion!$A$2:$I$85,7,FALSE),"") | S40: =IFERROR(VLOOKUP($A40,Recepcion!$A$2:$I$85,8,FALSE),"") | T40: =IFERROR(VLOOKUP($A40,Recepcion!$A$2:$I$85,9,FALSE),"")
...

Sheet Recepcion
A1: ID_EJEMPLAR | B1: TITULO | C1: AUTOR | D1: PRESENTE | E1: ACEPTADO | F1: ESTADO_FISICO | G1: RESPONSABLE | H1: HORA | I1: OBSERVACIONES
A2: CH-003 | B2: Acompañada, pero a solas con la vida | C2: Johana Brewne Kelly | D2: SÍ | E2: ACEPTADO
A3: INV-063 | B3: Acompañada, pero a solas con la vida | C3: Kelly Johana Brewne | D3: SÍ | E3: ACEPTADO
A4: INV-053 | B4: Bailando con Lobos | C4: Michael Blake | D4: SÍ | E4: ACEPTADO
A5: INV-009 | B5: Bajo la Luna de Mayo | C5: Gerardo Meneses | D5: SÍ | E5: ACEPTADO
A6: INV-049 | B6: Bajo la Misma Estrella | C6: John Green | D6: SÍ | E6: ACEPTADO
A7: INV-027 | B7: Boulevard | C7: Flor Salvador | D7: SÍ | E7: ACEPTADO
A8: INV-044 | B8: Chat Natacha Chat | C8: Luis Maria Pescetti | D8: SÍ | E8: ACEPTADO
A9: INV-056 | B9: ¿Chicos de la Calle o Trabajo Chico? | C9: Jose Manuel Grima, Alicia le Fur | D9: SÍ | E9: ACEPTADO
A10: INV-029 | B10: Cien Años de Soledad | C10: Gabriel Garcia Marquez | D10: SÍ | E10: ACEPTADO
A11: CH-002 | B11: Con el alma en la mano | C11: Perret Gentil Beatriz | D11: SÍ | E11: ACEPTADO
A12: INV-062 | B12: Con el alma en la mano | C12: Beatriz Perret Gentil | D12: SÍ | E12: ACEPTADO
A13: INV-007 | B13: Conversaciones con Dios | C13: Neale Donald | D13: SÍ | E13: ACEPTADO
... A85: INV-036 | B85: Veinte Poemas de Amor y una Cancion Desesperada | C85: Pablo Neruda | D85: SÍ | E85: ACEPTADO

Sheet Bibliografico
A1: ID_BIBLIOGRAFICO | B1: TITULO | C1: AUTOR | D1: EDITORIAL | E1: ISBN | F1: COPIAS | G1: FUENTES | H1: IDS_EJEMPLARES | I1: DUPLICADO
A2: BIB-001 | B2: Acompañada, pero a solas con la vida | C2: Johana Brewne Kelly | D2: San Barbara | E2: 9789585810358 | F2: 2 | G2: CH, INVENTARIO | H2: INV-063, CH-003 | I2: SÍ
A3: BIB-002 | B3: Bailando con Lobos | C3: Michael Blake | D3: RBA | F3: 1 | G3: INVENTARIO | H3: INV-053 | I3: NO
A4: BIB-003 | B4: Bajo la Luna de Mayo | C4: Gerardo Meneses | D4: Norma | F4: 1 | G4: INVENTARIO | H4: INV-009 | I4: NO
A5: BIB-004 | B5: Bajo la Misma Estrella | C5: John Green | D5: N/E | F5: 1 | G5: INVENTARIO | H5: INV-049 | I5: NO
A6: BIB-005 | B6: Boulevard | C6: Flor Salvador | D6: Naranja | F6: 1 | G6: INVENTARIO | H6: INV-027 | I6: NO
A7: BIB-006 | B7: Chat Natacha Chat | C7: Luis Maria Pescetti | D7: Alfaguara Juvenil | F7: 1 | G7: INVENTARIO | H7: INV-044 | I7: NO
A8: BIB-007 | B8: ¿Chicos de la Calle o Trabajo Chico? | C8: Jose Manuel Grima, Alicia le Fur | D8: Lumen Hymanitas | F8: 1 | G8: INVENTARIO | H8: INV-056 | I8: NO
A9: BIB-008 | B9: Cien Años de Soledad | C9: Gabriel Garcia Marquez | D9: Norma | F9: 1 | G9: INVENTARIO | H9: INV-029 | I9: NO
A10: BIB-009 | B10: Con el alma en la mano | C10: Perret Gentil Beatriz | D10: San Barbara | E10: 9789585837515 | F10: 2 | G10: CH, INVENTARIO | H10: INV-062, CH-002 | I10: SÍ
A11: BIB-010 | B11: Conversaciones con Dios | C11: Neale Donald | D11: Debolsillo | F11: 1 | G11: INVENTARIO | H11: INV-007 | I11: NO
A12: BIB-011 | B12: Cronicas de una Muerte Anunciada | C12: Gabriel Garcia Marquez | D12: N/E | F12: 1 | G12: INVENTARIO | H12: INV-050 | I12: NO
A13: BIB-012 | B13: Cuando despierte el viento | C13: Heredia Maria F. | D13: Norma | E13: 9789580009658 | F13: 1 | G13: CH | H13: CH-008 | I13: NO
A14: BIB-013 | B14: Cumbia Soul | C14: Maria T. Balogh | D14: Cool Way Press | E14: 9780990972914 | F14: 2 | G14: CH, INVENTARIO | H14: INV-067, CH-007 | I14: SÍ
A15: BIB-014 | B15: De Rejas y Amor | C15: Barreira Maria Arturo | D15: San Barbara | E15: 9789585837591 | F15: 2 | G15: CH, INVENTARIO | H15: INV-065, CH-005 | I15: SÍ
A16: BIB-015 | B16: Del Secuestro y Otras Muertes | C16: Camilo Romero | D16: Intermedio | F16: 1 | G16: INVENTARIO | H16: INV-023 | I16: NO
A17: BIB-016 | B17: Despues de el. Secuela | C17: Flor Salvador | D17: N/E | F17: 1 | G17: INVENTARIO | H17: INV-004 | I17: NO
A18: BIB-017 | B18: Duespues del Funeral | C18: Agatha Christie | D18: Circulo de Lectores | F18: 1 | G18: INVENTARIO | H18: INV-054 | I18: NO
A19: BIB-018 | B19: El Abrazo | C19: Bojunga Lygia | D19: Norma | E19: 9789580471578 | F19: 1 | G19: CH | H19: CH-011 | I19: NO
A20: BIB-019 | B20: El Alquimista | C20: Paulo Coelho | D20: N/E | F20: 1 | G20: INVENTARIO | H20: INV-013 | I20: NO
A21: BIB-020 | B21: El Camino de la Felicidad | C21: Jorge Bucay | D21: Debolsillo | F21: 1 | G21: INVENTARIO | H21: INV-005 | I21: NO
A22: BIB-021 | B22: El Cuaderno de Notas de Miguel | C22: Pedro Conrado Cudriz | D22: Sibila | F22: 1 | G22: INVENTARIO | H22: INV-021 | I22: NO
A23: BIB-022 | B23: El Dia del Odio | C23: Osorio Lizarazo | D23: N/E | F23: 1 | G23: INVENTARIO | H23: INV-045 | I23: NO
A24: BIB-023 | B24: El Diablo de la Botella | C24: Robert Louis Stevenson | D24: Norma | F24: 1 | G24: INVENTARIO | H24: INV-057 | I24: NO
A25: BIB-024 | B25: El Extraño Caso del DR. Jekylly MR. Hyde | C25: Stevenson | D25: Norma | F25: 1 | G25: INVENTARIO | H25: INV-035 | I25: NO
A26: BIB-025 | B26: El Higado de Prometeo | C26: Jorge Bustos | D26: Nobel | F26: 1 | G26: INVENTARIO | H26: INV-026 | I26: NO
A27: BIB-026 | B27: El joven Moriarty y la planta carnivora | C27: Rhei Sofía | D27: Norma | E27: 9789587768114 | F27: 1 | G27: CH | H27: CH-016 | I27: NO
A28: BIB-027 | B28: El Llano en Llamas | C28: Juan Rulfo | D28: N/E | F28: 1 | G28: INVENTARIO | H28: INV-033 | I28: NO
A29: BIB-028 | B29: El Lobo y los Siete Cabritos | C29: Christine NÖstlinger | D29: Norma | F29: 1 | G29: INVENTARIO | H29: INV-019 | I29: NO
A30: BIB-029 | B30: El Manuscrito Encontrado en Accra | C30: Paulo Coelho | D30: Grijalbo | F30: 1 | G30: INVENTARIO | H30: INV-025 | I30: NO
A31: BIB-030 | B31: El Mejor Poema del Mundo 2026 | C31: Celia Corral Cañas | D31: Ediciones Noel | F31: 1 | G31: INVENTARIO | H31: INV-011 | I31: NO
A32: BIB-031 | B32: El Paisaje de una Amistad | C32: Angel Esteban, Stephanie Panichelli | D32: Espasa e Hoy | F32: 1 | G32: INVENTARIO | H32: INV-024 | I32: NO
A33: BIB-032 | B33: El Quinto Dragon | C33: Paulina Aguilar Gutierrez | D33: Norma | F33: 1 | G33: INVENTARIO | H33: INV-010 | I33: NO
A34: BIB-033 | B34: El Refugio de Poder Olvidar | C34: Maria Cristina Ocampo de Manzano | D34: N/E | F34: 1 | G34: INVENTARIO | H34: INV-020 | I34: NO
A35: BIB-034 | B35: El Tunel | C35: Ernesto Sabato | D35: N/E | F35: 1 | G35: INVENTARIO | H35: INV-043 | I35: NO
A36: BIB-035 | B36: El Viejo y El Mar | C36: Ernest Hemingway | D36: Atenea | F36: 1 | G36: INVENTARIO | H36: INV-039 | I36: NO
A37: BIB-036 | B37: Emilio | C37: Castilla Julia M. | D37: Norma | E37: 9789580441496 | F37: 1 | G37: CH | H37: CH-013 | I37: NO
A38: BIB-037 | B38: En busca del Equilibrio | C38: Wayne Dyer | D38: Debolsillo | F38: 1 | G38: INVENTARIO | H38: INV-008 | I38: NO
A39: BIB-038 | B39: Entre Pecas y Lentejas | C39: Elena Dreser | D39: Educar | F39: 1 | G39: INVENTARIO | H39: INV-012 | I39: NO
A40: BIB-039 | B40: Foto Estudio Corazon | C40: Maria Fernanda Heredia | D40: Norma | F40: 1 | G40: INVENTARIO | H40: INV-047 | I40: NO
...

Sheet Duplicados
A1: GRUPO | B1: TITULO | C1: EDITORIAL | D1: IDS_EJEMPLARES | E1: FUENTES | F1: TIPO | G1: ACCION
A2: BIB-001 | B2: Acompañada, pero a solas con la vida | C2: San Barbara | D2: INV-063, CH-003 | E2: CH, INVENTARIO | F2: ENTRE_FUENTES | G2: Verificar físicamente. Si son ejemplares distintos, recibir ambos. Si es el mismo, recibir solo uno.
A3: BIB-009 | B3: Con el alma en la mano | C3: San Barbara | D3: INV-062, CH-002 | E3: CH, INVENTARIO | F3: ENTRE_FUENTES | G3: Verificar físicamente. Si son ejemplares distintos, recibir ambos. Si es el mismo, recibir solo uno.
A4: BIB-013 | B4: Cumbia Soul | C4: Cool Way Press | D4: INV-067, CH-007 | E4: CH, INVENTARIO | F4: ENTRE_FUENTES | G4: Verificar físicamente. Si son ejemplares distintos, recibir ambos. Si es el mismo, recibir solo uno.
A5: BIB-014 | B5: De Rejas y Amor | C5: San Barbara | D5: INV-065, CH-005 | E5: CH, INVENTARIO | F5: ENTRE_FUENTES | G5: Verificar físicamente. Si son ejemplares distintos, recibir ambos. Si es el mismo, recibir solo uno.
A6: BIB-045 | B6: La Celestina | C6: Atenea | D6: INV-016, INV-042 | E6: INVENTARIO | F6: MISMA_FUENTE | G6: Verificar físicamente. Si son ejemplares distintos, recibir ambos. Si es el mismo, recibir solo uno.
A7: BIB-046 | B7: La ciudad de mis dolientes | C7: San Barbara | D7: INV-061, CH-001 | E7: CH, INVENTARIO | F7: ENTRE_FUENTES | G7: Verificar físicamente. Si son ejemplares distintos, recibir ambos. Si es el mismo, recibir solo uno.
A8: BIB-049 | B8: La revelacion de la Decima | C8: San Barbara | D8: INV-064, CH-004 | E8: CH, INVENTARIO | F8: ENTRE_FUENTES | G8: Verificar físicamente. Si son ejemplares distintos, recibir ambos. Si es el mismo, recibir solo uno.
A9: BIB-051 | B9: Las Mujeres del Quijote | C9: N/E | D9: INV-030, INV-031 | E9: INVENTARIO | F9: MISMA_FUENTE | G9: Verificar físicamente. Si son ejemplares distintos, recibir ambos. Si es el mismo, recibir solo uno.
A10: BIB-059 | B10: Memorias de un acoso gris | C10: San Barbara | D10: INV-066, CH-006 | E10: CH, INVENTARIO | F10: ENTRE_FUENTES | G10: Verificar físicamente. Si son ejemplares distintos, recibir ambos. Si es el mismo, recibir solo uno.
A11: BIB-071 | B11: Relato de un Náufrago | C11: Norma | D11: INV-018, CH-017 | E11: CH, INVENTARIO | F11: ENTRE_FUENTES | G11: Verificar físicamente. Si son ejemplares distintos, recibir ambos. Si es el mismo, recibir solo uno.

Sheet Intercambios
A1: NO_OPERACION | B1: FECHA_HORA | C1: RESPONSABLE | D1: ID_APORTADO | E1: ID_ENTREGADO | F1: CODIGO_PARTICIPANTE | G1: ESTADO | H1: COMPROBANTE | I1: OBSERVACIONES | J1: VALIDACION
A4: ="EVT-"&TEXT(ROW()-3,"000") | G4: REGISTRADO | H4: =IF(J4="VÁLIDO",A4,"") | J4: =IF(COUNTA($D4,$E4)=0,"",IF($G4="ANULADO","ANULADO",IF($D4=$E4,"ERROR: MISMO EJEMPLAR",IF(IFERROR(VLOOKUP($D4,Catalogo!$A:$T,16,FALSE),"NO")<>"SÍ","ERROR: APORTADO NO DISPONIBLE",IF(IFERROR(VLOOKUP($E4,Catalogo!$A:$T,16,FALSE),"NO")<>"SÍ","ERROR: ENTREGADO NO DISPONIBLE",IF(COUNTIFS($D$4:$D$103,$D4,$G$4:$G$103,"REGISTRADO",$A$4:$A$103,"<>"&$A4)+COUNTIFS($E$4:$E$103,$D4,$G$4:$G$103,"REGISTRADO",$A$4:$A$103,"<>"&$A4)>0,"ERROR: APORTADO YA USADO",IF(COUNTIFS($D$4:$D$103,$E4,$G$4:$G$103,"REGISTRADO",$A$4:$A$103,"<>"&$A4)+COUNTIFS($E$4:$E$103,$E4,$G$4:$G$103,"REGISTRADO",$A$4:$A$103,"<>"&$A4)>0,"ERROR: ENTREGADO YA USADO","VÁLIDO")))))))
A5: ="EVT-"&TEXT(ROW()-3,"000") | G5: REGISTRADO | H5: =IF(J5="VÁLIDO",A5,"") | J5: =IF(COUNTA($D5,$E5)=0,"",IF($G5="ANULADO","ANULADO",IF($D5=$E5,"ERROR: MISMO EJEMPLAR",IF(IFERROR(VLOOKUP($D5,Catalogo!$A:$T,16,FALSE),"NO")<>"SÍ","ERROR: APORTADO NO DISPONIBLE",IF(IFERROR(VLOOKUP($E5,Catalogo!$A:$T,16,FALSE),"NO")<>"SÍ","ERROR: ENTREGADO NO DISPONIBLE",IF(COUNTIFS($D$4:$D$103,$D5,$G$4:$G$103,"REGISTRADO",$A$4:$A$103,"<>"&$A5)+COUNTIFS($E$4:$E$103,$D5,$G$4:$G$103,"REGISTRADO",$A$4:$A$103,"<>"&$A5)>0,"ERROR: APORTADO YA USADO",IF(COUNTIFS($D$4:$D$103,$E5,$G$4:$G$103,"REGISTRADO",$A$4:$A$103,"<>"&$A5)+COUNTIFS($E$4:$E$103,$E5,$G$4:$G$103,"REGISTRADO",$A$4:$A$103,"<>"&$A5)>0,"ERROR: ENTREGADO YA USADO","VÁLIDO")))))))
A6: ="EVT-"&TEXT(ROW()-3,"000") | G6: REGISTRADO | H6: =IF(J6="VÁLIDO",A6,"") | J6: =IF(COUNTA($D6,$E6)=0,"",IF($G6="ANULADO","ANULADO",IF($D6=$E6,"ERROR: MISMO EJEMPLAR",IF(IFERROR(VLOOKUP($D6,Catalogo!$A:$T,16,FALSE),"NO")<>"SÍ","ERROR: APORTADO NO DISPONIBLE",IF(IFERROR(VLOOKUP($E6,Catalogo!$A:$T,16,FALSE),"NO")<>"SÍ","ERROR: ENTREGADO NO DISPONIBLE",IF(COUNTIFS($D$4:$D$103,$D6,$G$4:$G$103,"REGISTRADO",$A$4:$A$103,"<>"&$A6)+COUNTIFS($E$4:$E$103,$D6,$G$4:$G$103,"REGISTRADO",$A$4:$A$103,"<>"&$A6)>0,"ERROR: APORTADO YA USADO",IF(COUNTIFS($D$4:$D$103,$E6,$G$4:$G$103,"REGISTRADO",$A$4:$A$103,"<>"&$A6)+COUNTIFS($E$4:$E$103,$E6,$G$4:$G$103,"REGISTRADO",$A$4:$A$103,"<>"&$A6)>0,"ERROR: ENTREGADO YA USADO","VÁLIDO")))))))
A7: ="EVT-"&TEXT(ROW()-3,"000") | G7: REGISTRADO | H7: =IF(J7="VÁLIDO",A7,"") | J7: =IF(COUNTA($D7,$E7)=0,"",IF($G7="ANULADO","ANULADO",IF($D7=$E7,"ERROR: MISMO EJEMPLAR",IF(IFERROR(VLOOKUP($D7,Catalogo!$A:$T,16,FALSE),"NO")<>"SÍ","ERROR: APORTADO NO DISPONIBLE",IF(IFERROR(VLOOKUP($E7,Catalogo!$A:$T,16,FALSE),"NO")<>"SÍ","ERROR: ENTREGADO NO DISPONIBLE",IF(COUNTIFS($D$4:$D$103,$D7,$G$4:$G$103,"REGISTRADO",$A$4:$A$103,"<>"&$A7)+COUNTIFS($E$4:$E$103,$D7,$G$4:$G$103,"REGISTRADO",$A$4:$A$103,"<>"&$A7)>0,"ERROR: APORTADO YA USADO",IF(COUNTIFS($D$4:$D$103,$E7,$G$4:$G$103,"REGISTRADO",$A$4:$A$103,"<>"&$A7)+COUNTIFS($E$4:$E$103,$E7,$G$4:$G$103,"REGISTRADO",$A$4:$A$103,"<>"&$A7)>0,"ERROR: ENTREGADO YA USADO","VÁLIDO")))))))
A8: ="EVT-"&TEXT(ROW()-3,"000") | G8: REGISTRADO | H8: =IF(J8="VÁLIDO",A8,"") | J8: =IF(COUNTA($D8,$E8)=0,"",IF($G8="ANULADO","ANULADO",IF($D8=$E8,"ERROR: MISMO EJEMPLAR",IF(IFERROR(VLOOKUP($D8,Catalogo!$A:$T,16,FALSE),"NO")<>"SÍ","ERROR: APORTADO NO DISPONIBLE",IF(IFERROR(VLOOKUP($E8,Catalogo!$A:$T,16,FALSE),"NO")<>"SÍ","ERROR: ENTREGADO NO DISPONIBLE",IF(COUNTIFS($D$4:$D$103,$D8,$G$4:$G$103,"REGISTRADO",$A$4:$A$103,"<>"&$A8)+COUNTIFS($E$4:$E$103,$D8,$G$4:$G$103,"REGISTRADO",$A$4:$A$103,"<>"&$A8)>0,"ERROR: APORTADO YA USADO",IF(COUNTIFS($D$4:$D$103,$E8,$G$4:$G$103,"REGISTRADO",$A$4:$A$103,"<>"&$A8)+COUNTIFS($E$4:$E$103,$E8,$G$4:$G$103,"REGISTRADO",$A$4:$A$103,"<>"&$A8)>0,"ERROR: ENTREGADO YA USADO","VÁLIDO")))))))
A9: ="EVT-"&TEXT(ROW()-3,"000") | G9: REGISTRADO | H9: =IF(J9="VÁLIDO",A9,"") | J9: =IF(COUNTA($D9,$E9)=0,"",IF($G9="ANULADO","ANULADO",IF($D9=$E9,"ERROR: MISMO EJEMPLAR",IF(IFERROR(VLOOKUP($D9,Catalogo!$A:$T,16,FALSE),"NO")<>"SÍ","ERROR: APORTADO NO DISPONIBLE",IF(IFERROR(VLOOKUP($E9,Catalogo!$A:$T,16,FALSE),"NO")<>"SÍ","ERROR: ENTREGADO NO DISPONIBLE",IF(COUNTIFS($D$4:$D$103,$D9,$G$4:$G$103,"REGISTRADO",$A$4:$A$103,"<>"&$A9)+COUNTIFS($E$4:$E$103,$D9,$G$4:$G$103,"REGISTRADO",$A$4:$A$103,"<>"&$A9)>0,"ERROR: APORTADO YA USADO",IF(COUNTIFS($D$4:$D$103,$E9,$G$4:$G$103,"REGISTRADO",$A$4:$A$103,"<>"&$A9)+COUNTIFS($E$4:$E$103,$E9,$G$4:$G$103,"REGISTRADO",$A$4:$A$103,"<>"&$A9)>0,"ERROR: ENTREGADO YA USADO","VÁLIDO")))))))
A10: ="EVT-"&TEXT(ROW()-3,"000") | G10: REGISTRADO | H10: =IF(J10="VÁLIDO",A10,"") | J10: =IF(COUNTA($D10,$E10)=0,"",IF($G10="ANULADO","ANULADO",IF($D10=$E10,"ERROR: MISMO EJEMPLAR",IF(IFERROR(VLOOKUP($D10,Catalogo!$A:$T,16,FALSE),"NO")<>"SÍ","ERROR: APORTADO NO DISPONIBLE",IF(IFERROR(VLOOKUP($E10,Catalogo!$A:$T,16,FALSE),"NO")<>"SÍ","ERROR: ENTREGADO NO DISPONIBLE",IF(COUNTIFS($D$4:$D$103,$D10,$G$4:$G$103,"REGISTRADO",$A$4:$A$103,"<>"&$A10)+COUNTIFS($E$4:$E$103,$D10,$G$4:$G$103,"REGISTRADO",$A$4:$A$103,"<>"&$A10)>0,"ERROR: APORTADO YA USADO",IF(COUNTIFS($D$4:$D$103,$E10,$G$4:$G$103,"REGISTRADO",$A$4:$A$103,"<>"&$A10)+COUNTIFS($E$4:$E$103,$E10,$G$4:$G$103,"REGISTRADO",$A$4:$A$103,"<>"&$A10)>0,"ERROR: ENTREGADO YA USADO","VÁLIDO")))))))
A11: ="EVT-"&TEXT(ROW()-3,"000") | G11: REGISTRADO | H11: =IF(J11="VÁLIDO",A11,"") | J11: =IF(COUNTA($D11,$E11)=0,"",IF($G11="ANULADO","ANULADO",IF($D11=$E11,"ERROR: MISMO EJEMPLAR",IF(IFERROR(VLOOKUP($D11,Catalogo!$A:$T,16,FALSE),"NO")<>"SÍ","ERROR: APORTADO NO DISPONIBLE",IF(IFERROR(VLOOKUP($E11,Catalogo!$A:$T,16,FALSE),"NO")<>"SÍ","ERROR: ENTREGADO NO DISPONIBLE",IF(COUNTIFS($D$4:$D$103,$D11,$G$4:$G$103,"REGISTRADO",$A$4:$A$103,"<>"&$A11)+COUNTIFS($E$4:$E$103,$D11,$G$4:$G$103,"REGISTRADO",$A$4:$A$103,"<>"&$A11)>0,"ERROR: APORTADO YA USADO",IF(COUNTIFS($D$4:$D$103,$E11,$G$4:$G$103,"REGISTRADO",$A$4:$A$103,"<>"&$A11)+COUNTIFS($E$4:$E$103,$E11,$G$4:$G$103,"REGISTRADO",$A$4:$A$103,"<>"&$A11)>0,"ERROR: ENTREGADO YA USADO","VÁLIDO")))))))
A12: ="EVT-"&TEXT(ROW()-3,"000") | G12: REGISTRADO | H12: =IF(J12="VÁLIDO",A12,"") | J12: =IF(COUNTA($D12,$E12)=0,"",IF($G12="ANULADO","ANULADO",IF($D12=$E12,"ERROR: MISMO EJEMPLAR",IF(IFERROR(VLOOKUP($D12,Catalogo!$A:$T,16,FALSE),"NO")<>"SÍ","ERROR: APORTADO NO DISPONIBLE",IF(IFERROR(VLOOKUP($E12,Catalogo!$A:$T,16,FALSE),"NO")<>"SÍ","ERROR: ENTREGADO NO DISPONIBLE",IF(COUNTIFS($D$4:$D$103,$D12,$G$4:$G$103,"REGISTRADO",$A$4:$A$103,"<>"&$A12)+COUNTIFS($E$4:$E$103,$D12,$G$4:$G$103,"REGISTRADO",$A$4:$A$103,"<>"&$A12)>0,"ERROR: APORTADO YA USADO",IF(COUNTIFS($D$4:$D$103,$E12,$G$4:$G$103,"REGISTRADO",$A$4:$A$103,"<>"&$A12)+COUNTIFS($E$4:$E$103,$E12,$G$4:$G$103,"REGISTRADO",$A$4:$A$103,"<>"&$A12)>0,"ERROR: ENTREGADO YA USADO","VÁLIDO")))))))
